WARNING: Requirement 'wxPython-4.0.1.tar.gz' looks like a filename, but the file does not exist
Processing ./wxPython-4.0.1.tar.gz
ERROR: Exception:
Traceback (most recent call last):
  File "/home/achakrav/.conda/envs/4dpls/lib/python3.7/site-packages/pip/_internal/cli/base_command.py", line 173, in _main
    status = self.run(options, args)
  File "/home/achakrav/.conda/envs/4dpls/lib/python3.7/site-packages/pip/_internal/cli/req_command.py", line 203, in wrapper
    return func(self, options, args)
  File "/home/achakrav/.conda/envs/4dpls/lib/python3.7/site-packages/pip/_internal/commands/wheel.py", line 141, in run
    reqs, check_supported_wheels=True
  File "/home/achakrav/.conda/envs/4dpls/lib/python3.7/site-packages/pip/_internal/resolution/resolvelib/resolver.py", line 75, in resolve
    collected = self.factory.collect_root_requirements(root_reqs)
  File "/home/achakrav/.conda/envs/4dpls/lib/python3.7/site-packages/pip/_internal/resolution/resolvelib/factory.py", line 473, in collect_root_requirements
    requested_extras=(),
  File "/home/achakrav/.conda/envs/4dpls/lib/python3.7/site-packages/pip/_internal/resolution/resolvelib/factory.py", line 438, in _make_requirement_from_install_req
    version=None,
  File "/home/achakrav/.conda/envs/4dpls/lib/python3.7/site-packages/pip/_internal/resolution/resolvelib/factory.py", line 209, in _make_candidate_from_link
    version=version,
  File "/home/achakrav/.conda/envs/4dpls/lib/python3.7/site-packages/pip/_internal/resolution/resolvelib/candidates.py", line 301, in __init__
    version=version,
  File "/home/achakrav/.conda/envs/4dpls/lib/python3.7/site-packages/pip/_internal/resolution/resolvelib/candidates.py", line 156, in __init__
    self.dist = self._prepare()
  File "/home/achakrav/.conda/envs/4dpls/lib/python3.7/site-packages/pip/_internal/resolution/resolvelib/candidates.py", line 227, in _prepare
    dist = self._prepare_distribution()
  File "/home/achakrav/.conda/envs/4dpls/lib/python3.7/site-packages/pip/_internal/resolution/resolvelib/candidates.py", line 306, in _prepare_distribution
    self._ireq, parallel_builds=True
  File "/home/achakrav/.conda/envs/4dpls/lib/python3.7/site-packages/pip/_internal/operations/prepare.py", line 508, in prepare_linked_requirement
    return self._prepare_linked_requirement(req, parallel_builds)
  File "/home/achakrav/.conda/envs/4dpls/lib/python3.7/site-packages/pip/_internal/operations/prepare.py", line 552, in _prepare_linked_requirement
    self.download_dir, hashes
  File "/home/achakrav/.conda/envs/4dpls/lib/python3.7/site-packages/pip/_internal/operations/prepare.py", line 249, in unpack_url
    unpack_file(file.path, location, file.content_type)
  File "/home/achakrav/.conda/envs/4dpls/lib/python3.7/site-packages/pip/_internal/utils/unpacking.py", line 253, in unpack_file
    or tarfile.is_tarfile(filename)
  File "/home/achakrav/.conda/envs/4dpls/lib/python3.7/tarfile.py", line 2440, in is_tarfile
    t = open(name)
  File "/home/achakrav/.conda/envs/4dpls/lib/python3.7/tarfile.py", line 1571, in open
    return func(name, "r", fileobj, **kwargs)
  File "/home/achakrav/.conda/envs/4dpls/lib/python3.7/tarfile.py", line 1636, in gzopen
    fileobj = gzip.GzipFile(name, mode + "b", compresslevel, fileobj)
  File "/home/achakrav/.conda/envs/4dpls/lib/python3.7/gzip.py", line 163, in __init__
    fileobj = self.myfileobj = builtins.open(filename, mode or 'rb')
FileNotFoundError: [Errno 2] No such file or directory: '/project_data/ramanan/achakrav/4D-PLS/wxPython-4.0.1.tar.gz'
